Workbook

Sheet Dashboard
B2: RCA MVP — Progress Tracker
B3: Updated 2026-06-09 - Verified from code - Track A 20/57 done - Track B 8/8 done · EPIC-005 tier catalogs deferred (Phase 1: all tools exposed)
B5: Overall
B6: Bucket | C6: Total | D6: Done | E6: In progress | F6: Blocked | G6: Not started
B7: Track A (Product) | C7: =COUNTA('Track A'!D2:D200) | D7: =COUNTIF('Track A'!D2:D200,"Done") | E7: =COUNTIF('Track A'!D2:D200,"In progress") | F7: =COUNTIF('Track A'!D2:D200,"Blocked") | G7: =COUNTIF('Track A'!D2:D200,"Not started")
B8: Track B (Simulators) | C8: =COUNTA('Track B'!E2:E200) | D8: =COUNTIF('Track B'!E2:E200,"Done") | E8: =COUNTIF('Track B'!E2:E200,"In progress") | F8: =COUNTIF('Track B'!E2:E200,"Blocked") | G8: =COUNTIF('Track B'!E2:E200,"Not started")
B9: Gaps | C9: =COUNTA(Gaps!D2:D20) | D9: =COUNTIF(Gaps!D2:D20,"Done") | E9: =COUNTIF(Gaps!D2:D20,"In progress") | F9: =COUNTIF(Gaps!D2:D20,"Blocked") | G9: =COUNTIF(Gaps!D2:D20,"Not started")
B12: Epics — Track A
B13: Epic | C13: Total | D13: Done | E13: In progress | F13: Blocked | G13: Status
B14: EPIC-001 Foundations | C14: =COUNTIF('Track A'!B2:B200,"S1.*") | D14: =COUNTIFS('Track A'!B2:B200,"S1.*",'Track A'!D2:D200,"Done") | E14: =COUNTIFS('Track A'!B2:B200,"S1.*",'Track A'!D2:D200,"In progress") | F14: =COUNTIFS('Track A'!B2:B200,"S1.*",'Track A'!D2:D200,"Blocked") | G14: =IF(D14=C14,"✓ Done",IF(E14>0,"In progress",IF(F14>0,"Blocked","Not started")))
B15: EPIC-012 MAR | C15: =COUNTIF('Track A'!B2:B200,"S12.*") | D15: =COUNTIFS('Track A'!B2:B200,"S12.*",'Track A'!D2:D200,"Done") | E15: =COUNTIFS('Track A'!B2:B200,"S12.*",'Track A'!D2:D200,"In progress") | F15: =COUNTIFS('Track A'!B2:B200,"S12.*",'Track A'!D2:D200,"Blocked") | G15: =IF(D15=C15,"✓ Done",IF(E15>0,"In progress",IF(F15>0,"Blocked","Not started")))
B16: EPIC-003 TRS | C16: =COUNTIF('Track A'!B2:B200,"S3.*") | D16: =COUNTIFS('Track A'!B2:B200,"S3.*",'Track A'!D2:D200,"Done") | E16: =COUNTIFS('Track A'!B2:B200,"S3.*",'Track A'!D2:D200,"In progress") | F16: =COUNTIFS('Track A'!B2:B200,"S3.*",'Track A'!D2:D200,"Blocked") | G16: =IF(D16=C16,"✓ Done",IF(E16>0,"In progress",IF(F16>0,"Blocked","Not started")))
B17: EPIC-004 Templates | C17: =COUNTIF('Track A'!B2:B200,"S4.*") | D17: =COUNTIFS('Track A'!B2:B200,"S4.*",'Track A'!D2:D200,"Done") | E17: =COUNTIFS('Track A'!B2:B200,"S4.*",'Track A'!D2:D200,"In progress") | F17: =COUNTIFS('Track A'!B2:B200,"S4.*",'Track A'!D2:D200,"Blocked") | G17: =IF(D17=C17,"✓ Done",IF(E17>0,"In progress",IF(F17>0,"Blocked","Not started")))
B18: EPIC-013 Connectors | C18: =COUNTIF('Track A'!B2:B200,"S13.*") | D18: =COUNTIFS('Track A'!B2:B200,"S13.*",'Track A'!D2:D200,"Done") | E18: =COUNTIFS('Track A'!B2:B200,"S13.*",'Track A'!D2:D200,"In progress") | F18: =COUNTIFS('Track A'!B2:B200,"S13.*",'Track A'!D2:D200,"Blocked") | G18: =IF(D18=C18,"✓ Done",IF(E18>0,"In progress",IF(F18>0,"Blocked","Not started")))
B19: EPIC-005 MCP | C19: =COUNTIF('Track A'!B2:B200,"S5.*") | D19: =COUNTIFS('Track A'!B2:B200,"S5.*",'Track A'!D2:D200,"Done") | E19: =COUNTIFS('Track A'!B2:B200,"S5.*",'Track A'!D2:D200,"In progress") | F19: =COUNTIFS('Track A'!B2:B200,"S5.*",'Track A'!D2:D200,"Blocked") | G19: =IF(D19=C19,"✓ Done",IF(E19>0,"In progress",IF(F19>0,"Blocked","Not started")))
B20: EPIC-006 Temporal | C20: =COUNTIF('Track A'!B2:B200,"S6.*") | D20: =COUNTIFS('Track A'!B2:B200,"S6.*",'Track A'!D2:D200,"Done") | E20: =COUNTIFS('Track A'!B2:B200,"S6.*",'Track A'!D2:D200,"In progress") | F20: =COUNTIFS('Track A'!B2:B200,"S6.*",'Track A'!D2:D200,"Blocked") | G20: =IF(D20=C20,"✓ Done",IF(E20>0,"In progress",IF(F20>0,"Blocked","Not started")))
B21: EPIC-007 Agents | C21: =COUNTIF('Track A'!B2:B200,"S7.*") | D21: =COUNTIFS('Track A'!B2:B200,"S7.*",'Track A'!D2:D200,"Done") | E21: =COUNTIFS('Track A'!B2:B200,"S7.*",'Track A'!D2:D200,"In progress") | F21: =COUNTIFS('Track A'!B2:B200,"S7.*",'Track A'!D2:D200,"Blocked") | G21: =IF(D21=C21,"✓ Done",IF(E21>0,"In progress",IF(F21>0,"Blocked","Not started")))
B22: EPIC-008 HITL UI | C22: =COUNTIF('Track A'!B2:B200,"S8.*") | D22: =COUNTIFS('Track A'!B2:B200,"S8.*",'Track A'!D2:D200,"Done") | E22: =COUNTIFS('Track A'!B2:B200,"S8.*",'Track A'!D2:D200,"In progress") | F22: =COUNTIFS('Track A'!B2:B200,"S8.*",'Track A'!D2:D200,"Blocked") | G22: =IF(D22=C22,"✓ Done",IF(E22>0,"In progress",IF(F22>0,"Blocked","Not started")))
B23: EPIC-009 Eval | C23: =COUNTIF('Track A'!B2:B200,"S9.*") | D23: =COUNTIFS('Track A'!B2:B200,"S9.*",'Track A'!D2:D200,"Done") | E23: =COUNTIFS('Track A'!B2:B200,"S9.*",'Track A'!D2:D200,"In progress") | F23: =COUNTIFS('Track A'!B2:B200,"S9.*",'Track A'!D2:D200,"Blocked") | G23: =IF(D23=C23,"✓ Done",IF(E23>0,"In progress",IF(F23>0,"Blocked","Not started")))
B24: EPIC-010 Observability | C24: =COUNTIF('Track A'!B2:B200,"S10.*") | D24: =COUNTIFS('Track A'!B2:B200,"S10.*",'Track A'!D2:D200,"Done") | E24: =COUNTIFS('Track A'!B2:B200,"S10.*",'Track A'!D2:D200,"In progress") | F24: =COUNTIFS('Track A'!B2:B200,"S10.*",'Track A'!D2:D200,"Blocked") | G24: =IF(D24=C24,"✓ Done",IF(E24>0,"In progress",IF(F24>0,"Blocked","Not started")))
B25: EPIC-011 Pilot | C25: =COUNTIF('Track A'!B2:B200,"S11.*") | D25: =COUNTIFS('Track A'!B2:B200,"S11.*",'Track A'!D2:D200,"Done") | E25: =COUNTIFS('Track A'!B2:B200,"S11.*",'Track A'!D2:D200,"In progress") | F25: =COUNTIFS('Track A'!B2:B200,"S11.*",'Track A'!D2:D200,"Blocked") | G25: =IF(D25=C25,"✓ Done",IF(E25>0,"In progress",IF(F25>0,"Blocked","Not started")))
B28: Epics — Track B
B29: Epic | C29: Total | D29: Done | E29: In progress | F29: Blocked | G29: Status
B30: EPIC-002 Simulators | C30: =COUNTA('Track B'!E2:E200) | D30: =COUNTIF('Track B'!E2:E200,"Done") | E30: =COUNTIF('Track B'!E2:E200,"In progress") | F30: =COUNTIF('Track B'!E2:E200,"Blocked") | G30: =IF(D30=C30,"✓ Done",IF(E30>0,"In progress",IF(F30>0,"Blocked","Not started")))
B33: This Week
B34: Week | C34: Track A focus | E34: Track B focus
B35: W1 (Jun 8-12) | C35: S1.1 monorepo, S1.2 contracts, S1.3 docker-compose | E35: S2.1 fixture + S2.8 realism (Days 1-2), then S2.7 MQTT (Days 3-4)

Sheet Burn-up
B2: 12-Week Burn-up Plan
B4: Week | C4: Track A plan | D4: Track B plan | E4: Planned stories | F4: Actual done | G4: Notes
B5: W1 (Jun 8-12) | C5: Contracts, monorepo, docker-compose, Alembic | D5: Fixture loader, MQTT sim, OPC UA sim | E5: 8
B6: W2 (Jun 15-19) | C6: MAR schemas + resolve + get + search | D6: SharePoint/S3 sim | E6: 8
B7: W3 (Jun 22-26) | C7: TRS schemas + resolve_tag, Templates loader | D7: PI sim | E7: 8
B8: W4 (Jun 29-Jul 3) | C8: connector_sdk, MCP tier registration | D8: Maximo sim, SAP sim | E8: 8
B9: W5 (Jul 6-10) | C9: PI connector vs PI sim, MCP catalog | D9: Realism harness | E9: 6
B10: W6 (Jul 13-17) | C10: Maximo connector vs Maximo sim | D10: (complete) | E10: 4
B11: W7 (Jul 20-24) | C11: SAP/Document connectors, Temporal probe | D11: — | E11: 6
B12: W8 (Jul 27-31) | C12: Tier 1-2 agents (Scope, Evidence) | D12: — | E12: 4
B13: W9 (Aug 3-7) | C13: Tier 3-4 agents (Reason, Govern) + HITL UI | D13: — | E13: 5
B14: W10 (Aug 10-14) | C14: Eval harness + golden set | D14: — | E14: 4
B15: W11 (Aug 17-21) | C15: Observability, cost dashboard | D15: — | E15: 3
B16: W12 (Aug 24-28) | C16: Pilot: parity tests, customer configs, runbook | D16: — | E16: 4

Sheet Track A
B1: ID | C1: Story | D1: Tracker (Jun-4) | E1: Verified (Jun-9) | F1: Diff | G1: Dep | H1: Notes | I1: Docs
B2: S1.1 | C2: Monorepo setup (packages/, infra/, scripts/, tests/) | D2: Not started | E2: Done | F2: up ahead | G2: — | I2: docs/foundations/EPIC-001-foundations.md
B3: S1.2 | C3: Pydantic v2 contracts (closes G1: AssetDescriptor, TagDescriptor, ProbeTrigger, etc.) | D3: Not started | E3: Done | F3: up ahead | G3: — | H3: SPEC-001 + SPEC-012 | I3: docs/foundations/SPEC-001-evidence-bundle.md + SPEC-012
B4: S1.3 | C4: docker-compose dev stack (Postgres, Neo4j, Temporal, MinIO) | D4: Not started | E4: Done | F4: up ahead | G4: — | I4: docs/foundations/WEEK-1-QUICKSTART.md
B5: S1.4 | C5: Alembic migrations baseline | D5: Not started | E5: Done | F5: up ahead | G5: S1.3 | I5: docs/foundations/EPIC-001-foundations.md
B6: S1.5 | C6: Round-trip contract test | D6: Not started | E6: Done | F6: up ahead | G6: S1.2 | I6: docs/foundations/SPEC-001-evidence-bundle.md
B7: S12.1 | C7: MAR schemas + Postgres tables | D7: Not started | E7: Done | F7: up ahead | G7: S1.2, S1.4 | I7: docs/mar/SPEC-011-master-asset-registry.md
B8: S12.2 | C8: MAR.resolve(name/site) → asset_id | D8: Not started | E8: Done | F8: up ahead | G8: S12.1 | I8: docs/mar/SPEC-011-master-asset-registry.md
B9: S12.3 | C9: MAR.get(asset_id) → AssetDescriptor | D9: Not started | E9: Done | F9: up ahead | G9: S12.1 | I9: docs/mar/SPEC-011-master-asset-registry.md
B10: S12.4 | C10: MAR.search + hierarchy traversal | D10: Not started | E10: Done | F10: up ahead | G10: S12.1 | I10: docs/mar/SPEC-011-master-asset-registry.md
B11: S12.5 | C11: MAR ↔ PI AF source adapter | D11: Not started | E11: Not started | F11: = | G11: S13.2 | H11: Sim-backed first | I11: docs/mar/EPIC-012-master-asset-registry.md
B12: S12.6 | C12: MAR ↔ Maximo source adapter | D12: Not started | E12: Not started | F12: = | G12: S13.3 | H12: Sim-backed first | I12: docs/mar/EPIC-012-master-asset-registry.md
B13: S12.7 | C13: MAR ↔ Spreadsheet bootstrap | D13: Not started | E13: Not started | F13: = | G13: S13.6 | I13: docs/mar/EPIC-012-master-asset-registry.md
B14: S12.8 | C14: MAR ↔ SAP PM adapter | D14: Not started | E14: Not started | F14: = | G14: S13.4 | H14: Sim-backed first | I14: docs/mar/EPIC-012-master-asset-registry.md
B15: S3.1 | C15: TRS schemas + Postgres tables | D15: Not started | E15: Done | F15: up ahead | G15: S1.2, S1.4 | I15: docs/trs/SPEC-003-tag-resolution-service.md
B16: S3.2 | C16: TRS.resolve_tag(tag) → tag_id + meta | D16: Not started | E16: Done | F16: up ahead | G16: S3.1 | I16: docs/trs/SPEC-003-tag-resolution-service.md
B17: S3.3 | C17: TRS.search + TRS.get | D17: Not started | E17: Done | F17: up ahead | G17: S3.1 | I17: docs/trs/SPEC-003-tag-resolution-service.md
B18: S3.4 | C18: UNS BIRTH/DEATH consumer → TRS upserts | D18: Not started | E18: Not started | F18: = | G18: S3.1, S13.7 | I18: docs/trs/EPIC-003-trs.md
B19: S3.5 | C19: PI AF tag enumeration → TRS | D19: Not started | E19: Not started | F19: = | G19: S13.2 | H19: Sim-backed first | I19: docs/trs/EPIC-003-trs.md
B20: S3.6 | C20: Unresolved-tag queue + HITL hook | D20: Not started | E20: Not started | F20: = | G20: S3.2 | I20: docs/trs/EPIC-003-trs.md
B21: S4.1 | C21: Template loader + validator | D21: Not started | E21: Not started | F21: = | G21: S1.2 | H21: SPEC-015 | I21: docs/templates/SPEC-015-equipment-template-schema.md
B22: S4.2 | C22: Centrifugal pump template v0.3.1 | D22: Not started | E22: Not started | F22: = | G22: S4.1 | H22: From rca_pump_ref_bundle | I22: docs/templates/SPEC-015-equipment-template-schema.md
B23: S4.3 | C23: MCP tools: template.get / list / validate | D23: Not started | E23: Not started | F23: = | G23: S4.1, S5.1 | I23: docs/templates/EPIC-004-templates.md
B24: S4.4 | C24: Overlay enforcement (customer overrides base) | D24: Not started | E24: Not started | F24: = | G24: S4.1 | I24: docs/templates/SPEC-010-overlay-learning.md
B25: S13.1 | C25: connector_sdk: BaseConnector ABC + lifecycle (UNBLOCKS ALL OTHERS) | D25: Not started | E25: Done | F25: up ahead | G25: S1.2 | H25: ADR-0012 | I25: docs/connectors/EPIC-013-connectors.md + SPEC-002
B26: S13.2 | C26: PI connector (Web API + AF) | D26: Not started | E26: Done | F26: up ahead | G26: S13.1, S2.2 | I26: docs/connectors/EPIC-013-connectors.md
B27: S13.3 | C27: Maximo connector (REST) | D27: Not started | E27: Done | F27: up ahead | G27: S13.1, S2.3 | I27: docs/connectors/EPIC-013-connectors.md
B28: S13.4 | C28: SAP PM connector (OData) | D28: Not started | E28: Done | F28: up ahead | G28: S13.1, S2.4 | I28: docs/connectors/EPIC-013-connectors.md
B29: S13.5 | C29: OPC UA connector | D29: Not started | E29: Done | F29: up ahead | G29: S13.1, S2.5 | I29: docs/connectors/EPIC-013-connectors.md
B30: S13.6 | C30: Document connector (SharePoint/S3) | D30: Not started | E30: Done | F30: up ahead | G30: S13.1, S2.6 | I30: docs/connectors/EPIC-013-connectors.md
B31: S13.7 | C31: MQTT/UNS connector | D31: Not started | E31: Done | F31: up ahead | G31: S13.1, S2.7 | I31: docs/connectors/EPIC-013-connectors.md
B32: S13.8 | C32: Contract tests: connector ↔ simulator parity | D32: Not started | E32: Done | F32: up ahead | G32: S13.2-S13.7 | I32: docs/connectors/EPIC-013-connectors.md
B33: S13.9 | C33: Credential broker integration | D33: Not started | E33: In progress | F33: up ahead | G33: S13.1 | I33: docs/connectors/SPEC-002-mcp-tool-contracts.md
B34: S5.1 | C34: MCP tier registration + auth | D34: Not started | E34: Not started | F34: Deferred | G34: — | I34: docs/mcp/EPIC-005-mcp-servers.md
B35: S5.2 | C35: MCP catalog per tier (Tier 1-4) | D35: Not started | E35: Not started | F35: Deferred | G35: — | I35: docs/mcp/EPIC-005-mcp-servers.md
B36: S5.3 | C36: Rate limit + budget guard | D36: Not started | E36: Not started | F36: Deferred | G36: — | I36: docs/mcp/EPIC-005-mcp-servers.md
B37: S6.1 | C37: Probe workflow skeleton | D37: Not started | E37: Not started | F37: = | G37: S1.2 | I37: docs/temporal/SPEC-004-probe-workflow.md
B38: S6.2 | C38: Probe trigger ingestion + dedup | D38: Not started | E38: Not started | F38: = | G38: S6.1 | H38: SPEC-012 | I38: docs/temporal/SPEC-012-probe-trigger-schema.md
B39: S6.3 | C39: HITL signals (approve/reject/escalate) | D39: Not started | E39: Not started | F39: = | G39: S6.1 | I39: docs/hitl/SPEC-005-hitl-gates.md
B40: S6.4 | C40: Tenant onboarding workflow | D40: Not started | E40: Not started | F40: = | G40: S6.1 | H40: SPEC-013 | I40: docs/foundations/SPEC-013-tenant-onboarding.md
...

Sheet Track B
B1: Order | C1: ID | D1: Story | E1: Tracker (Jun-4) | F1: Verified (Jun-9) | G1: Diff | H1: Dep | I1: Docs | J1: Notes
B2: 1 | C2: S2.1 | D2: Fixture loader + manifest schema ⚑ FOUNDATION — start here | E2: Not started | F2: Done | G2: up ahead | H2: S1.2 | I2: docs/simulators/SPEC-014-simulator-fixture-schema.md | J2: Blocks S2.2-S2.7. Day 1-2.
B3: 2 | C3: S2.8 | D3: Realism harness (drift, jitter, fault injection) ⚑ FOUNDATION | E3: Not started | F3: Done | G3: up ahead | H3: S2.1 | I3: docs/simulators/SPEC-007-simulator-behavior.md | J3: Day 1-2, parallel with S2.1.
B4: 3 | C4: S2.7 | D4: MQTT/UNS simulator (Mosquitto + Sparkplug B publisher) | E4: Not started | F4: Done | G4: up ahead | H4: S2.1 | I4: docs/simulators/EPIC-002-simulators.md §S2.7 | J4: Day 3-4. Simplest — just publish bytes. Validates fixture loader end-to-end.
B5: 4 | C5: S2.5 | D5: OPC UA simulator (asyncua server + nodes) | E5: Not started | F5: Done | G5: up ahead | H5: S2.1 | I5: docs/simulators/EPIC-002-simulators.md §S2.5 | J5: Day 5-7. Well-documented protocol.
B6: 5 | C6: S2.6 | D6: SharePoint / S3 document simulator (FastAPI + MinIO) | E6: Not started | F6: Done | G6: up ahead | H6: S2.1 | I6: docs/simulators/EPIC-002-simulators.md §S2.6 | J6: Week 2. Documents for evidence.
B7: 6 | C7: S2.2 | D7: PI Historian simulator (PI Web API REST subset) | E7: Not started | F7: Done | G7: up ahead | H7: S2.1 | I7: docs/simulators/EPIC-002-simulators.md §S2.2 | J7: Week 3. Most surface area; biggest payback.
B8: 7 | C8: S2.3 | D8: Maximo simulator (OSLC REST: work orders, assets, locations) | E8: Not started | F8: Done | G8: up ahead | H8: S2.1 | I8: docs/simulators/EPIC-002-simulators.md §S2.3 | J8: Week 4. CMMS data.
B9: 8 | C9: S2.4 | D9: SAP PM simulator (OData v2: equipment, notifications) | E9: Not started | F9: Done | G9: up ahead | H9: S2.1 | I9: docs/simulators/EPIC-002-simulators.md §S2.4 | J9: Week 4, parallel with Maximo.

Sheet Blockers
B2: Active Blockers
B3: Add rows as blockers are discovered. Status auto-colors.
B5: Opened | C5: Story | D5: Description | E5: Owner | F5: Status | G5: Resolution

Sheet Decisions
B2: Decision Log
B3: Architecture and process decisions. Promote significant ones to ADRs in docs/adrs/.
B5: Date | C5: Decision | D5: Context / Rationale | E5: Outcome
B6: 2026-06-04 | C6: Connectors own the MCP contract; simulators stand in for sources | D6: Original framing put simulators as 'fake connectors,' which made connector + simulator look like one workstream. Reframed to clarify: connectors are the integration layer; simulators implement the same source-side interface as real systems. | E6: Promoted to ADR-0012; unblocks parallel Track B work
B7: 2026-06-09 | C7: Skip tier-bounded tool catalogs for Phase 1 MVP; expose all MCP tools | D7: With only ~5-10 tools total, per-tier catalog filtering (EPIC-005 S5.1/S5.2) solves problems that don't bite at this scale: context bloat and least-privilege isolation only pay off at large tool counts. Phase 1 agents receive the full toolset from the connected MCP servers directly. | E7: EPIC-005 tier work deferred to post-Phase-1. Revisit when tool count grows or Govern-tier write-backs need guarding. ADR-0005 / SPEC-002 tier-catalog language now aspirational, not Phase-1.

Sheet Gaps
B2: Gap Tracker
B3: Must-fix gaps identified pre-kickoff. G2-G6 closed by SPEC-001/012/013/014/015.
B5: Gap | C5: Description | D5: Status | E5: Closed by | F5: Owner / Notes
B6: G1 | C6: Pydantic v2 contracts not yet implemented | D6: In progress | E6: S1.2 (spec ready) | F6: Code authored in Claude Code
B7: G2 | C7: AssetDescriptor / TagDescriptor not formally specified | D7: Done | E7: SPEC-001 patch | F7: Closed pre-kickoff
B8: G3 | C8: Probe trigger schema undefined | D8: Done | E8: SPEC-012 | F8: Closed pre-kickoff
B9: G4 | C9: Tenant onboarding workflow undefined | D9: Done | E9: SPEC-013 | F9: Closed pre-kickoff
B10: G5 | C10: Simulator fixture schema undefined | D10: Done | E10: SPEC-014 | F10: Closed pre-kickoff
B11: G6 | C11: Equipment template schema undefined | D11: Done | E11: SPEC-015 | F11: Closed pre-kickoff
B12: G7 | C12: Auth & credential broker spec | D12: Not started | E12: Deferred | F12: Post-W4
B13: G8 | C13: Knowledge graph schema (Neo4j) | D13: Not started | E13: Deferred | F13: Tier 3 work
B14: G9 | C14: Probe state machine formalization | D14: Not started | E14: Deferred | F14: Folded into S6.1
B15: G10 | C15: Budget enforcement spec | D15: Not started | E15: Deferred | F15: S5.3 covers basics
B16: G11 | C16: Eval scoring rubric | D16: Not started | E16: Deferred | F16: S9.2 will define
B17: G12 | C17: Multi-tenant isolation guarantees | D17: Not started | E17: Deferred | F17: Post-MVP

Sheet Lessons
B2: Lessons Learned
B3: Capture insights as they emerge — what worked, what didn't, what to change.
B5: Date | C5: Topic | D5: Lesson | E5: Action / Follow-up
B6: 2026-06-04 | C6: Simulators | D6: Sim vibration is trend-only (scalar RMS trends, no FFT spectra). Acceptable for MVP — agent reasons on thresholds/trends from the template. | E6: Pilot validation against real PI data must cover spectrum cases (1x/2x/broadband signatures).
